Workbook

Sheet Aug
A1: สรุปภาพรวมผลการดำเนินงานสาขา (Area Performance Dashboard)
A2: ="เดือน (Month): "&IF(Aug!B107="","(ยังไม่ระบุ)",Aug!B107)&" | จำนวนสาขาที่รายงาน: "&COUNTIF(Aug!A111:A125,"?*")&" สาขา" -> เดือน (Month): (ยังไม่ระบุ) | จำนวนสาขาที่รายงาน: 0 สาขา
A4: ยอดขายรวม (Sales) | D4: กำไร EBIT รวม (฿) | G4: ต้นทุนขาย COGs รวม | J4: ค่าแรง COL รวม (฿)
A5: ="2025: "&TEXT(SUM(Aug!B111:B125),"#,##0")&" 2026: "&TEXT(SUM(Aug!C111:C125),"#,##0") -> 2025: 0 2026: 0 | D5: ="2025: "&TEXT(SUM(Aug!E111:E125),"#,##0")&" 2026: "&TEXT(SUM(Aug!F111:F125),"#,##0") -> 2025: 0 2026: 0 | G5: ="2025: "&TEXT(SUM(Aug!T111:T125),"#,##0")&" 2026: "&TEXT(SUM(Aug!U111:U125),"#,##0") -> 2025: 0 2026: 0 | J5: ="2025: "&TEXT(SUM(Aug!W111:W125),"#,##0")&" 2026: "&TEXT(SUM(Aug!X111:X125),"#,##0") -> 2025: 0 2026: 0
A6: =IFERROR(TEXT((SUM(Aug!C111:C125)-SUM(Aug!B111:B125))/SUM(Aug!B111:B125),"+0.0%;-0.0%")&" YoY","-") -> - | D6: =IFERROR(TEXT((SUM(Aug!F111:F125)-SUM(Aug!E111:E125))/SUM(Aug!E111:E125),"+0.0%;-0.0%")&" YoY","-") -> - | G6: =IFERROR(TEXT((SUM(Aug!U111:U125)-SUM(Aug!T111:T125))/SUM(Aug!T111:T125),"+0.0%;-0.0%")&" YoY","-") -> - | J6: =IFERROR(TEXT((SUM(Aug!X111:X125)-SUM(Aug!W111:W125))/SUM(Aug!W111:W125),"+0.0%;-0.0%")&" YoY","-") -> -
A8: ข้อร้องเรียนรวม (Complaint) | D8: OT รวม (ชม./บาท)
A9: =TEXT(SUM(Aug!AE111:AE125),"#,##0") -> 0 | D9: =TEXT(SUM(Aug!AC111:AC125),"#,##0") -> 0
A12: ผลการดำเนินงานรายสาขา (Branch Performance) — เทียบ YoY
A13: สาขา (Branch) | B13: ยอดขาย YoY% | C13: EBIT YoY% | D13: COL% to Sales Δ | E13: Complaint | F13: สถานะ / ประเด็นที่พบ | O13: ProblemScore | P13: ProblemKey | Q13: RankProblem | R13: RankBest
A14: =IF(Aug!A111="","",Aug!A111) | B14: =IF(Aug!A111="","",Aug!D111) | C14: =IF(Aug!A111="","",Aug!G111) | D14: =IF(Aug!A111="","",Aug!AB111) | E14: =IF(Aug!A111="","",Aug!AE111) | F14: =IF(A14="","",IF((IF(B14<0,"ยอดขายลด, ","")&IF(C14<0,"กำไรลด, ","")&IF(D14>0,"ต้นทุนแรงงาน/ยอดขายเพิ่ม, ","")&IF(E14>=3,"ร้องเรียนเยอะ, ",""))="","ปกติ / ดี",IF(RIGHT(IF(B14<0,"ยอดขายลด, ","")&IF(C14<0,"กำไรลด, ","")&IF(D14>0,"ต้นทุนแรงงาน/ยอดขายเพิ่ม, ","")&IF(E14>=3,"ร้องเรียนเยอะ, ",""),2)=", ",LEFT(IF(B14<0,"ยอดขายลด, ","")&IF(C14<0,"กำไรลด, ","")&IF(D14>0,"ต้นทุนแรงงาน/ยอดขายเพิ่ม, ","")&IF(E14>=3,"ร้องเรียนเยอะ, ",""),LEN(IF(B14<0,"ยอดขายลด, ","")&IF(C14<0,"กำไรลด, ","")&IF(D14>0,"ต้นทุนแรงงาน/ยอดขายเพิ่ม, ","")&IF(E14>=3,"ร้องเรียนเยอะ, ",""))-2),IF(B14<0,"ยอดขายลด, ","")&IF(C14<0,"กำไรลด, ","")&IF(D14>0,"ต้นทุนแรงงาน/ยอดขายเพิ่ม, ","")&IF(E14>=3,"ร้องเรียนเยอะ, ","")))) | O14: =IF(A14="","",(B14<0)*1+(C14<0)*1+(D14>0)*1+(E14>=3)*1) | P14: =IF(A14="","",O14-IFERROR(B14/1000,0)) | Q14: =IF(A14="","",IFERROR(RANK(P14,$P$14:$P$36)+COUNTIF($P$14:P14,P14)-1,"")) | R14: =IF(A14="","",IFERROR(RANK(B14,$B$14:$B$36)+COUNTIF($B$14:B14,B14)-1,""))
A15: =IF(Aug!A112="","",Aug!A112) | B15: =IF(Aug!A112="","",Aug!D112) | C15: =IF(Aug!A112="","",Aug!G112) | D15: =IF(Aug!A112="","",Aug!AB112) | E15: =IF(Aug!A112="","",Aug!AE112) | F15: =IF(A15="","",IF((IF(B15<0,"ยอดขายลด, ","")&IF(C15<0,"กำไรลด, ","")&IF(D15>0,"ต้นทุนแรงงาน/ยอดขายเพิ่ม, ","")&IF(E15>=3,"ร้องเรียนเยอะ, ",""))="","ปกติ / ดี",IF(RIGHT(IF(B15<0,"ยอดขายลด, ","")&IF(C15<0,"กำไรลด, ","")&IF(D15>0,"ต้นทุนแรงงาน/ยอดขายเพิ่ม, ","")&IF(E15>=3,"ร้องเรียนเยอะ, ",""),2)=", ",LEFT(IF(B15<0,"ยอดขายลด, ","")&IF(C15<0,"กำไรลด, ","")&IF(D15>0,"ต้นทุนแรงงาน/ยอดขายเพิ่ม, ","")&IF(E15>=3,"ร้องเรียนเยอะ, ",""),LEN(IF(B15<0,"ยอดขายลด, ","")&IF(C15<0,"กำไรลด, ","")&IF(D15>0,"ต้นทุนแรงงาน/ยอดขายเพิ่ม, ","")&IF(E15>=3,"ร้องเรียนเยอะ, ",""))-2),IF(B15<0,"ยอดขายลด, ","")&IF(C15<0,"กำไรลด, ","")&IF(D15>0,"ต้นทุนแรงงาน/ยอดขายเพิ่ม, ","")&IF(E15>=3,"ร้องเรียนเยอะ, ","")))) | O15: =IF(A15="","",(B15<0)*1+(C15<0)*1+(D15>0)*1+(E15>=3)*1) | P15: =IF(A15="","",O15-IFERROR(B15/1000,0)) | Q15: =IF(A15="","",IFERROR(RANK(P15,$P$14:$P$36)+COUNTIF($P$14:P15,P15)-1,"")) | R15: =IF(A15="","",IFERROR(RANK(B15,$B$14:$B$36)+COUNTIF($B$14:B15,B15)-1,""))
A16: =IF(Aug!A113="","",Aug!A113) | B16: =IF(Aug!A113="","",Aug!D113) | C16: =IF(Aug!A113="","",Aug!G113) | D16: =IF(Aug!A113="","",Aug!AB113) | E16: =IF(Aug!A113="","",Aug!AE113) | F16: =IF(A16="","",IF((IF(B16<0,"ยอดขายลด, ","")&IF(C16<0,"กำไรลด, ","")&IF(D16>0,"ต้นทุนแรงงาน/ยอดขายเพิ่ม, ","")&IF(E16>=3,"ร้องเรียนเยอะ, ",""))="","ปกติ / ดี",IF(RIGHT(IF(B16<0,"ยอดขายลด, ","")&IF(C16<0,"กำไรลด, ","")&IF(D16>0,"ต้นทุนแรงงาน/ยอดขายเพิ่ม, ","")&IF(E16>=3,"ร้องเรียนเยอะ, ",""),2)=", ",LEFT(IF(B16<0,"ยอดขายลด, ","")&IF(C16<0,"กำไรลด, ","")&IF(D16>0,"ต้นทุนแรงงาน/ยอดขายเพิ่ม, ","")&IF(E16>=3,"ร้องเรียนเยอะ, ",""),LEN(IF(B16<0,"ยอดขายลด, ","")&IF(C16<0,"กำไรลด, ","")&IF(D16>0,"ต้นทุนแรงงาน/ยอดขายเพิ่ม, ","")&IF(E16>=3,"ร้องเรียนเยอะ, ",""))-2),IF(B16<0,"ยอดขายลด, ","")&IF(C16<0,"กำไรลด, ","")&IF(D16>0,"ต้นทุนแรงงาน/ยอดขายเพิ่ม, ","")&IF(E16>=3,"ร้องเรียนเยอะ, ","")))) | O16: =IF(A16="","",(B16<0)*1+(C16<0)*1+(D16>0)*1+(E16>=3)*1) | P16: =IF(A16="","",O16-IFERROR(B16/1000,0)) | Q16: =IF(A16="","",IFERROR(RANK(P16,$P$14:$P$36)+COUNTIF($P$14:P16,P16)-1,"")) | R16: =IF(A16="","",IFERROR(RANK(B16,$B$14:$B$36)+COUNTIF($B$14:B16,B16)-1,""))
A17: =IF(Aug!A114="","",Aug!A114) | B17: =IF(Aug!A114="","",Aug!D114) | C17: =IF(Aug!A114="","",Aug!G114) | D17: =IF(Aug!A114="","",Aug!AB114) | E17: =IF(Aug!A114="","",Aug!AE114) | F17: =IF(A17="","",IF((IF(B17<0,"ยอดขายลด, ","")&IF(C17<0,"กำไรลด, ","")&IF(D17>0,"ต้นทุนแรงงาน/ยอดขายเพิ่ม, ","")&IF(E17>=3,"ร้องเรียนเยอะ, ",""))="","ปกติ / ดี",IF(RIGHT(IF(B17<0,"ยอดขายลด, ","")&IF(C17<0,"กำไรลด, ","")&IF(D17>0,"ต้นทุนแรงงาน/ยอดขายเพิ่ม, ","")&IF(E17>=3,"ร้องเรียนเยอะ, ",""),2)=", ",LEFT(IF(B17<0,"ยอดขายลด, ","")&IF(C17<0,"กำไรลด, ","")&IF(D17>0,"ต้นทุนแรงงาน/ยอดขายเพิ่ม, ","")&IF(E17>=3,"ร้องเรียนเยอะ, ",""),LEN(IF(B17<0,"ยอดขายลด, ","")&IF(C17<0,"กำไรลด, ","")&IF(D17>0,"ต้นทุนแรงงาน/ยอดขายเพิ่ม, ","")&IF(E17>=3,"ร้องเรียนเยอะ, ",""))-2),IF(B17<0,"ยอดขายลด, ","")&IF(C17<0,"กำไรลด, ","")&IF(D17>0,"ต้นทุนแรงงาน/ยอดขายเพิ่ม, ","")&IF(E17>=3,"ร้องเรียนเยอะ, ","")))) | O17: =IF(A17="","",(B17<0)*1+(C17<0)*1+(D17>0)*1+(E17>=3)*1) | P17: =IF(A17="","",O17-IFERROR(B17/1000,0)) | Q17: =IF(A17="","",IFERROR(RANK(P17,$P$14:$P$36)+COUNTIF($P$14:P17,P17)-1,"")) | R17: =IF(A17="","",IFERROR(RANK(B17,$B$14:$B$36)+COUNTIF($B$14:B17,B17)-1,""))
A18: =IF(Aug!A115="","",Aug!A115) | B18: =IF(Aug!A115="","",Aug!D115) | C18: =IF(Aug!A115="","",Aug!G115) | D18: =IF(Aug!A115="","",Aug!AB115) | E18: =IF(Aug!A115="","",Aug!AE115) | F18: =IF(A18="","",IF((IF(B18<0,"ยอดขายลด, ","")&IF(C18<0,"กำไรลด, ","")&IF(D18>0,"ต้นทุนแรงงาน/ยอดขายเพิ่ม, ","")&IF(E18>=3,"ร้องเรียนเยอะ, ",""))="","ปกติ / ดี",IF(RIGHT(IF(B18<0,"ยอดขายลด, ","")&IF(C18<0,"กำไรลด, ","")&IF(D18>0,"ต้นทุนแรงงาน/ยอดขายเพิ่ม, ","")&IF(E18>=3,"ร้องเรียนเยอะ, ",""),2)=", ",LEFT(IF(B18<0,"ยอดขายลด, ","")&IF(C18<0,"กำไรลด, ","")&IF(D18>0,"ต้นทุนแรงงาน/ยอดขายเพิ่ม, ","")&IF(E18>=3,"ร้องเรียนเยอะ, ",""),LEN(IF(B18<0,"ยอดขายลด, ","")&IF(C18<0,"กำไรลด, ","")&IF(D18>0,"ต้นทุนแรงงาน/ยอดขายเพิ่ม, ","")&IF(E18>=3,"ร้องเรียนเยอะ, ",""))-2),IF(B18<0,"ยอดขายลด, ","")&IF(C18<0,"กำไรลด, ","")&IF(D18>0,"ต้นทุนแรงงาน/ยอดขายเพิ่ม, ","")&IF(E18>=3,"ร้องเรียนเยอะ, ","")))) | O18: =IF(A18="","",(B18<0)*1+(C18<0)*1+(D18>0)*1+(E18>=3)*1) | P18: =IF(A18="","",O18-IFERROR(B18/1000,0)) | Q18: =IF(A18="","",IFERROR(RANK(P18,$P$14:$P$36)+COUNTIF($P$14:P18,P18)-1,"")) | R18: =IF(A18="","",IFERROR(RANK(B18,$B$14:$B$36)+COUNTIF($B$14:B18,B18)-1,""))
A19: =IF(Aug!A116="","",Aug!A116) | B19: =IF(Aug!A116="","",Aug!D116) | C19: =IF(Aug!A116="","",Aug!G116) | D19: =IF(Aug!A116="","",Aug!AB116) | E19: =IF(Aug!A116="","",Aug!AE116) | F19: =IF(A19="","",IF((IF(B19<0,"ยอดขายลด, ","")&IF(C19<0,"กำไรลด, ","")&IF(D19>0,"ต้นทุนแรงงาน/ยอดขายเพิ่ม, ","")&IF(E19>=3,"ร้องเรียนเยอะ, ",""))="","ปกติ / ดี",IF(RIGHT(IF(B19<0,"ยอดขายลด, ","")&IF(C19<0,"กำไรลด, ","")&IF(D19>0,"ต้นทุนแรงงาน/ยอดขายเพิ่ม, ","")&IF(E19>=3,"ร้องเรียนเยอะ, ",""),2)=", ",LEFT(IF(B19<0,"ยอดขายลด, ","")&IF(C19<0,"กำไรลด, ","")&IF(D19>0,"ต้นทุนแรงงาน/ยอดขายเพิ่ม, ","")&IF(E19>=3,"ร้องเรียนเยอะ, ",""),LEN(IF(B19<0,"ยอดขายลด, ","")&IF(C19<0,"กำไรลด, ","")&IF(D19>0,"ต้นทุนแรงงาน/ยอดขายเพิ่ม, ","")&IF(E19>=3,"ร้องเรียนเยอะ, ",""))-2),IF(B19<0,"ยอดขายลด, ","")&IF(C19<0,"กำไรลด, ","")&IF(D19>0,"ต้นทุนแรงงาน/ยอดขายเพิ่ม, ","")&IF(E19>=3,"ร้องเรียนเยอะ, ","")))) | O19: =IF(A19="","",(B19<0)*1+(C19<0)*1+(D19>0)*1+(E19>=3)*1) | P19: =IF(A19="","",O19-IFERROR(B19/1000,0)) | Q19: =IF(A19="","",IFERROR(RANK(P19,$P$14:$P$36)+COUNTIF($P$14:P19,P19)-1,"")) | R19: =IF(A19="","",IFERROR(RANK(B19,$B$14:$B$36)+COUNTIF($B$14:B19,B19)-1,""))
A20: =IF(Aug!A117="","",Aug!A117) | B20: =IF(Aug!A117="","",Aug!D117) | C20: =IF(Aug!A117="","",Aug!G117) | D20: =IF(Aug!A117="","",Aug!AB117) | E20: =IF(Aug!A117="","",Aug!AE117) | F20: =IF(A20="","",IF((IF(B20<0,"ยอดขายลด, ","")&IF(C20<0,"กำไรลด, ","")&IF(D20>0,"ต้นทุนแรงงาน/ยอดขายเพิ่ม, ","")&IF(E20>=3,"ร้องเรียนเยอะ, ",""))="","ปกติ / ดี",IF(RIGHT(IF(B20<0,"ยอดขายลด, ","")&IF(C20<0,"กำไรลด, ","")&IF(D20>0,"ต้นทุนแรงงาน/ยอดขายเพิ่ม, ","")&IF(E20>=3,"ร้องเรียนเยอะ, ",""),2)=", ",LEFT(IF(B20<0,"ยอดขายลด, ","")&IF(C20<0,"กำไรลด, ","")&IF(D20>0,"ต้นทุนแรงงาน/ยอดขายเพิ่ม, ","")&IF(E20>=3,"ร้องเรียนเยอะ, ",""),LEN(IF(B20<0,"ยอดขายลด, ","")&IF(C20<0,"กำไรลด, ","")&IF(D20>0,"ต้นทุนแรงงาน/ยอดขายเพิ่ม, ","")&IF(E20>=3,"ร้องเรียนเยอะ, ",""))-2),IF(B20<0,"ยอดขายลด, ","")&IF(C20<0,"กำไรลด, ","")&IF(D20>0,"ต้นทุนแรงงาน/ยอดขายเพิ่ม, ","")&IF(E20>=3,"ร้องเรียนเยอะ, ","")))) | O20: =IF(A20="","",(B20<0)*1+(C20<0)*1+(D20>0)*1+(E20>=3)*1) | P20: =IF(A20="","",O20-IFERROR(B20/1000,0)) | Q20: =IF(A20="","",IFERROR(RANK(P20,$P$14:$P$36)+COUNTIF($P$14:P20,P20)-1,"")) | R20: =IF(A20="","",IFERROR(RANK(B20,$B$14:$B$36)+COUNTIF($B$14:B20,B20)-1,""))
A21: =IF(Aug!A118="","",Aug!A118) | B21: =IF(Aug!A118="","",Aug!D118) | C21: =IF(Aug!A118="","",Aug!G118) | D21: =IF(Aug!A118="","",Aug!AB118) | E21: =IF(Aug!A118="","",Aug!AE118) | F21: =IF(A21="","",IF((IF(B21<0,"ยอดขายลด, ","")&IF(C21<0,"กำไรลด, ","")&IF(D21>0,"ต้นทุนแรงงาน/ยอดขายเพิ่ม, ","")&IF(E21>=3,"ร้องเรียนเยอะ, ",""))="","ปกติ / ดี",IF(RIGHT(IF(B21<0,"ยอดขายลด, ","")&IF(C21<0,"กำไรลด, ","")&IF(D21>0,"ต้นทุนแรงงาน/ยอดขายเพิ่ม, ","")&IF(E21>=3,"ร้องเรียนเยอะ, ",""),2)=", ",LEFT(IF(B21<0,"ยอดขายลด, ","")&IF(C21<0,"กำไรลด, ","")&IF(D21>0,"ต้นทุนแรงงาน/ยอดขายเพิ่ม, ","")&IF(E21>=3,"ร้องเรียนเยอะ, ",""),LEN(IF(B21<0,"ยอดขายลด, ","")&IF(C21<0,"กำไรลด, ","")&IF(D21>0,"ต้นทุนแรงงาน/ยอดขายเพิ่ม, ","")&IF(E21>=3,"ร้องเรียนเยอะ, ",""))-2),IF(B21<0,"ยอดขายลด, ","")&IF(C21<0,"กำไรลด, ","")&IF(D21>0,"ต้นทุนแรงงาน/ยอดขายเพิ่ม, ","")&IF(E21>=3,"ร้องเรียนเยอะ, ","")))) | O21: =IF(A21="","",(B21<0)*1+(C21<0)*1+(D21>0)*1+(E21>=3)*1) | P21: =IF(A21="","",O21-IFERROR(B21/1000,0)) | Q21: =IF(A21="","",IFERROR(RANK(P21,$P$14:$P$36)+COUNTIF($P$14:P21,P21)-1,"")) | R21: =IF(A21="","",IFERROR(RANK(B21,$B$14:$B$36)+COUNTIF($B$14:B21,B21)-1,""))
A22: =IF(Aug!A119="","",Aug!A119) | B22: =IF(Aug!A119="","",Aug!D119) | C22: =IF(Aug!A119="","",Aug!G119) | D22: =IF(Aug!A119="","",Aug!AB119) | E22: =IF(Aug!A119="","",Aug!AE119) | F22: =IF(A22="","",IF((IF(B22<0,"ยอดขายลด, ","")&IF(C22<0,"กำไรลด, ","")&IF(D22>0,"ต้นทุนแรงงาน/ยอดขายเพิ่ม, ","")&IF(E22>=3,"ร้องเรียนเยอะ, ",""))="","ปกติ / ดี",IF(RIGHT(IF(B22<0,"ยอดขายลด, ","")&IF(C22<0,"กำไรลด, ","")&IF(D22>0,"ต้นทุนแรงงาน/ยอดขายเพิ่ม, ","")&IF(E22>=3,"ร้องเรียนเยอะ, ",""),2)=", ",LEFT(IF(B22<0,"ยอดขายลด, ","")&IF(C22<0,"กำไรลด, ","")&IF(D22>0,"ต้นทุนแรงงาน/ยอดขายเพิ่ม, ","")&IF(E22>=3,"ร้องเรียนเยอะ, ",""),LEN(IF(B22<0,"ยอดขายลด, ","")&IF(C22<0,"กำไรลด, ","")&IF(D22>0,"ต้นทุนแรงงาน/ยอดขายเพิ่ม, ","")&IF(E22>=3,"ร้องเรียนเยอะ, ",""))-2),IF(B22<0,"ยอดขายลด, ","")&IF(C22<0,"กำไรลด, ","")&IF(D22>0,"ต้นทุนแรงงาน/ยอดขายเพิ่ม, ","")&IF(E22>=3,"ร้องเรียนเยอะ, ","")))) | O22: =IF(A22="","",(B22<0)*1+(C22<0)*1+(D22>0)*1+(E22>=3)*1) | P22: =IF(A22="","",O22-IFERROR(B22/1000,0)) | Q22: =IF(A22="","",IFERROR(RANK(P22,$P$14:$P$36)+COUNTIF($P$14:P22,P22)-1,"")) | R22: =IF(A22="","",IFERROR(RANK(B22,$B$14:$B$36)+COUNTIF($B$14:B22,B22)-1,""))
A23: =IF(Aug!A120="","",Aug!A120) | B23: =IF(Aug!A120="","",Aug!D120) | C23: =IF(Aug!A120="","",Aug!G120) | D23: =IF(Aug!A120="","",Aug!AB120) | E23: =IF(Aug!A120="","",Aug!AE120) | F23: =IF(A23="","",IF((IF(B23<0,"ยอดขายลด, ","")&IF(C23<0,"กำไรลด, ","")&IF(D23>0,"ต้นทุนแรงงาน/ยอดขายเพิ่ม, ","")&IF(E23>=3,"ร้องเรียนเยอะ, ",""))="","ปกติ / ดี",IF(RIGHT(IF(B23<0,"ยอดขายลด, ","")&IF(C23<0,"กำไรลด, ","")&IF(D23>0,"ต้นทุนแรงงาน/ยอดขายเพิ่ม, ","")&IF(E23>=3,"ร้องเรียนเยอะ, ",""),2)=", ",LEFT(IF(B23<0,"ยอดขายลด, ","")&IF(C23<0,"กำไรลด, ","")&IF(D23>0,"ต้นทุนแรงงาน/ยอดขายเพิ่ม, ","")&IF(E23>=3,"ร้องเรียนเยอะ, ",""),LEN(IF(B23<0,"ยอดขายลด, ","")&IF(C23<0,"กำไรลด, ","")&IF(D23>0,"ต้นทุนแรงงาน/ยอดขายเพิ่ม, ","")&IF(E23>=3,"ร้องเรียนเยอะ, ",""))-2),IF(B23<0,"ยอดขายลด, ","")&IF(C23<0,"กำไรลด, ","")&IF(D23>0,"ต้นทุนแรงงาน/ยอดขายเพิ่ม, ","")&IF(E23>=3,"ร้องเรียนเยอะ, ","")))) | O23: =IF(A23="","",(B23<0)*1+(C23<0)*1+(D23>0)*1+(E23>=3)*1) | P23: =IF(A23="","",O23-IFERROR(B23/1000,0)) | Q23: =IF(A23="","",IFERROR(RANK(P23,$P$14:$P$36)+COUNTIF($P$14:P23,P23)-1,"")) | R23: =IF(A23="","",IFERROR(RANK(B23,$B$14:$B$36)+COUNTIF($B$14:B23,B23)-1,""))
A24: =IF(Aug!A121="","",Aug!A121) | B24: =IF(Aug!A121="","",Aug!D121) | C24: =IF(Aug!A121="","",Aug!G121) | D24: =IF(Aug!A121="","",Aug!AB121) | E24: =IF(Aug!A121="","",Aug!AE121) | F24: =IF(A24="","",IF((IF(B24<0,"ยอดขายลด, ","")&IF(C24<0,"กำไรลด, ","")&IF(D24>0,"ต้นทุนแรงงาน/ยอดขายเพิ่ม, ","")&IF(E24>=3,"ร้องเรียนเยอะ, ",""))="","ปกติ / ดี",IF(RIGHT(IF(B24<0,"ยอดขายลด, ","")&IF(C24<0,"กำไรลด, ","")&IF(D24>0,"ต้นทุนแรงงาน/ยอดขายเพิ่ม, ","")&IF(E24>=3,"ร้องเรียนเยอะ, ",""),2)=", ",LEFT(IF(B24<0,"ยอดขายลด, ","")&IF(C24<0,"กำไรลด, ","")&IF(D24>0,"ต้นทุนแรงงาน/ยอดขายเพิ่ม, ","")&IF(E24>=3,"ร้องเรียนเยอะ, ",""),LEN(IF(B24<0,"ยอดขายลด, ","")&IF(C24<0,"กำไรลด, ","")&IF(D24>0,"ต้นทุนแรงงาน/ยอดขายเพิ่ม, ","")&IF(E24>=3,"ร้องเรียนเยอะ, ",""))-2),IF(B24<0,"ยอดขายลด, ","")&IF(C24<0,"กำไรลด, ","")&IF(D24>0,"ต้นทุนแรงงาน/ยอดขายเพิ่ม, ","")&IF(E24>=3,"ร้องเรียนเยอะ, ","")))) | O24: =IF(A24="","",(B24<0)*1+(C24<0)*1+(D24>0)*1+(E24>=3)*1) | P24: =IF(A24="","",O24-IFERROR(B24/1000,0)) | Q24: =IF(A24="","",IFERROR(RANK(P24,$P$14:$P$36)+COUNTIF($P$14:P24,P24)-1,"")) | R24: =IF(A24="","",IFERROR(RANK(B24,$B$14:$B$36)+COUNTIF($B$14:B24,B24)-1,""))
A25: =IF(Aug!A122="","",Aug!A122) | B25: =IF(Aug!A122="","",Aug!D122) | C25: =IF(Aug!A122="","",Aug!G122) | D25: =IF(Aug!A122="","",Aug!AB122) | E25: =IF(Aug!A122="","",Aug!AE122) | F25: =IF(A25="","",IF((IF(B25<0,"ยอดขายลด, ","")&IF(C25<0,"กำไรลด, ","")&IF(D25>0,"ต้นทุนแรงงาน/ยอดขายเพิ่ม, ","")&IF(E25>=3,"ร้องเรียนเยอะ, ",""))="","ปกติ / ดี",IF(RIGHT(IF(B25<0,"ยอดขายลด, ","")&IF(C25<0,"กำไรลด, ","")&IF(D25>0,"ต้นทุนแรงงาน/ยอดขายเพิ่ม, ","")&IF(E25>=3,"ร้องเรียนเยอะ, ",""),2)=", ",LEFT(IF(B25<0,"ยอดขายลด, ","")&IF(C25<0,"กำไรลด, ","")&IF(D25>0,"ต้นทุนแรงงาน/ยอดขายเพิ่ม, ","")&IF(E25>=3,"ร้องเรียนเยอะ, ",""),LEN(IF(B25<0,"ยอดขายลด, ","")&IF(C25<0,"กำไรลด, ","")&IF(D25>0,"ต้นทุนแรงงาน/ยอดขายเพิ่ม, ","")&IF(E25>=3,"ร้องเรียนเยอะ, ",""))-2),IF(B25<0,"ยอดขายลด, ","")&IF(C25<0,"กำไรลด, ","")&IF(D25>0,"ต้นทุนแรงงาน/ยอดขายเพิ่ม, ","")&IF(E25>=3,"ร้องเรียนเยอะ, ","")))) | O25: =IF(A25="","",(B25<0)*1+(C25<0)*1+(D25>0)*1+(E25>=3)*1) | P25: =IF(A25="","",O25-IFERROR(B25/1000,0)) | Q25: =IF(A25="","",IFERROR(RANK(P25,$P$14:$P$36)+COUNTIF($P$14:P25,P25)-1,"")) | R25: =IF(A25="","",IFERROR(RANK(B25,$B$14:$B$36)+COUNTIF($B$14:B25,B25)-1,""))
... A28: =IF(Aug!A125="","",Aug!A125) | B28: =IF(Aug!A125="","",Aug!D125) | C28: =IF(Aug!A125="","",Aug!G125) | D28: =IF(Aug!A125="","",Aug!AB125) | E28: =IF(Aug!A125="","",Aug!AE125) | F28: =IF(A28="","",IF((IF(B28<0,"ยอดขายลด, ","")&IF(C28<0,"กำไรลด, ","")&IF(D28>0,"ต้นทุนแรงงาน/ยอดขายเพิ่ม, ","")&IF(E28>=3,"ร้องเรียนเยอะ, ",""))="","ปกติ / ดี",IF(RIGHT(IF(B28<0,"ยอดขายลด, ","")&IF(C28<0,"กำไรลด, ","")&IF(D28>0,"ต้นทุนแรงงาน/ยอดขายเพิ่ม, ","")&IF(E28>=3,"ร้องเรียนเยอะ, ",""),2)=", ",LEFT(IF(B28<0,"ยอดขายลด, ","")&IF(C28<0,"กำไรลด, ","")&IF(D28>0,"ต้นทุนแรงงาน/ยอดขายเพิ่ม, ","")&IF(E28>=3,"ร้องเรียนเยอะ, ",""),LEN(IF(B28<0,"ยอดขายลด, ","")&IF(C28<0,"กำไรลด, ","")&IF(D28>0,"ต้นทุนแรงงาน/ยอดขายเพิ่ม, ","")&IF(E28>=3,"ร้องเรียนเยอะ, ",""))-2),IF(B28<0,"ยอดขายลด, ","")&IF(C28<0,"กำไรลด, ","")&IF(D28>0,"ต้นทุนแรงงาน/ยอดขายเพิ่ม, ","")&IF(E28>=3,"ร้องเรียนเยอะ, ","")))) | O28: =IF(A28="","",(B28<0)*1+(C28<0)*1+(D28>0)*1+(E28>=3)*1) | P28: =IF(A28="","",O28-IFERROR(B28/1000,0)) | Q28: =IF(A28="","",IFERROR(RANK(P28,$P$14:$P$36)+COUNTIF($P$14:P28,P28)-1,"")) | R28: =IF(A28="","",IFERROR(RANK(B28,$B$14:$B$36)+COUNTIF($B$14:B28,B28)-1,""))
F29: =IF(A29="","",IF((IF(B29<0,"ยอดขายลด, ","")&IF(C29<0,"กำไรลด, ","")&IF(D29>0,"ต้นทุนแรงงาน/ยอดขายเพิ่ม, ","")&IF(E29>=3,"ร้องเรียนเยอะ, ",""))="","ปกติ / ดี",IF(RIGHT(IF(B29<0,"ยอดขายลด, ","")&IF(C29<0,"กำไรลด, ","")&IF(D29>0,"ต้นทุนแรงงาน/ยอดขายเพิ่ม, ","")&IF(E29>=3,"ร้องเรียนเยอะ, ",""),2)=", ",LEFT(IF(B29<0,"ยอดขายลด, ","")&IF(C29<0,"กำไรลด, ","")&IF(D29>0,"ต้นทุนแรงงาน/ยอดขายเพิ่ม, ","")&IF(E29>=3,"ร้องเรียนเยอะ, ",""),LEN(IF(B29<0,"ยอดขายลด, ","")&IF(C29<0,"กำไรลด, ","")&IF(D29>0,"ต้นทุนแรงงาน/ยอดขายเพิ่ม, ","")&IF(E29>=3,"ร้องเรียนเยอะ, ",""))-2),IF(B29<0,"ยอดขายลด, ","")&IF(C29<0,"กำไรลด, ","")&IF(D29>0,"ต้นทุนแรงงาน/ยอดขายเพิ่ม, ","")&IF(E29>=3,"ร้องเรียนเยอะ, ","")))) | O29: =IF(A29="","",(B29<0)*1+(C29<0)*1+(D29>0)*1+(E29>=3)*1) | P29: =IF(A29="","",O29-IFERROR(B29/1000,0)) | Q29: =IF(A29="","",IFERROR(RANK(P29,$P$14:$P$36)+COUNTIF($P$14:P29,P29)-1,"")) | R29: =IF(A29="","",IFERROR(RANK(B29,$B$14:$B$36)+COUNTIF($B$14:B29,B29)-1,""))
F30: =IF(A30="","",IF((IF(B30<0,"ยอดขายลด, ","")&IF(C30<0,"กำไรลด, ","")&IF(D30>0,"ต้นทุนแรงงาน/ยอดขายเพิ่ม, ","")&IF(E30>=3,"ร้องเรียนเยอะ, ",""))="","ปกติ / ดี",IF(RIGHT(IF(B30<0,"ยอดขายลด, ","")&IF(C30<0,"กำไรลด, ","")&IF(D30>0,"ต้นทุนแรงงาน/ยอดขายเพิ่ม, ","")&IF(E30>=3,"ร้องเรียนเยอะ, ",""),2)=", ",LEFT(IF(B30<0,"ยอดขายลด, ","")&IF(C30<0,"กำไรลด, ","")&IF(D30>0,"ต้นทุนแรงงาน/ยอดขายเพิ่ม, ","")&IF(E30>=3,"ร้องเรียนเยอะ, ",""),LEN(IF(B30<0,"ยอดขายลด, ","")&IF(C30<0,"กำไรลด, ","")&IF(D30>0,"ต้นทุนแรงงาน/ยอดขายเพิ่ม, ","")&IF(E30>=3,"ร้องเรียนเยอะ, ",""))-2),IF(B30<0,"ยอดขายลด, ","")&IF(C30<0,"กำไรลด, ","")&IF(D30>0,"ต้นทุนแรงงาน/ยอดขายเพิ่ม, ","")&IF(E30>=3,"ร้องเรียนเยอะ, ","")))) | O30: =IF(A30="","",(B30<0)*1+(C30<0)*1+(D30>0)*1+(E30>=3)*1) | P30: =IF(A30="","",O30-IFERROR(B30/1000,0)) | Q30: =IF(A30="","",IFERROR(RANK(P30,$P$14:$P$36)+COUNTIF($P$14:P30,P30)-1,"")) | R30: =IF(A30="","",IFERROR(RANK(B30,$B$14:$B$36)+COUNTIF($B$14:B30,B30)-1,""))
F31: =IF(A31="","",IF((IF(B31<0,"ยอดขายลด, ","")&IF(C31<0,"กำไรลด, ","")&IF(D31>0,"ต้นทุนแรงงาน/ยอดขายเพิ่ม, ","")&IF(E31>=3,"ร้องเรียนเยอะ, ",""))="","ปกติ / ดี",IF(RIGHT(IF(B31<0,"ยอดขายลด, ","")&IF(C31<0,"กำไรลด, ","")&IF(D31>0,"ต้นทุนแรงงาน/ยอดขายเพิ่ม, ","")&IF(E31>=3,"ร้องเรียนเยอะ, ",""),2)=", ",LEFT(IF(B31<0,"ยอดขายลด, ","")&IF(C31<0,"กำไรลด, ","")&IF(D31>0,"ต้นทุนแรงงาน/ยอดขายเพิ่ม, ","")&IF(E31>=3,"ร้องเรียนเยอะ, ",""),LEN(IF(B31<0,"ยอดขายลด, ","")&IF(C31<0,"กำไรลด, ","")&IF(D31>0,"ต้นทุนแรงงาน/ยอดขายเพิ่ม, ","")&IF(E31>=3,"ร้องเรียนเยอะ, ",""))-2),IF(B31<0,"ยอดขายลด, ","")&IF(C31<0,"กำไรลด, ","")&IF(D31>0,"ต้นทุนแรงงาน/ยอดขายเพิ่ม, ","")&IF(E31>=3,"ร้องเรียนเยอะ, ","")))) | O31: =IF(A31="","",(B31<0)*1+(C31<0)*1+(D31>0)*1+(E31>=3)*1) | P31: =IF(A31="","",O31-IFERROR(B31/1000,0)) | Q31: =IF(A31="","",IFERROR(RANK(P31,$P$14:$P$36)+COUNTIF($P$14:P31,P31)-1,"")) | R31: =IF(A31="","",IFERROR(RANK(B31,$B$14:$B$36)+COUNTIF($B$14:B31,B31)-1,""))
F32: =IF(A32="","",IF((IF(B32<0,"ยอดขายลด, ","")&IF(C32<0,"กำไรลด, ","")&IF(D32>0,"ต้นทุนแรงงาน/ยอดขายเพิ่ม, ","")&IF(E32>=3,"ร้องเรียนเยอะ, ",""))="","ปกติ / ดี",IF(RIGHT(IF(B32<0,"ยอดขายลด, ","")&IF(C32<0,"กำไรลด, ","")&IF(D32>0,"ต้นทุนแรงงาน/ยอดขายเพิ่ม, ","")&IF(E32>=3,"ร้องเรียนเยอะ, ",""),2)=", ",LEFT(IF(B32<0,"ยอดขายลด, ","")&IF(C32<0,"กำไรลด, ","")&IF(D32>0,"ต้นทุนแรงงาน/ยอดขายเพิ่ม, ","")&IF(E32>=3,"ร้องเรียนเยอะ, ",""),LEN(IF(B32<0,"ยอดขายลด, ","")&IF(C32<0,"กำไรลด, ","")&IF(D32>0,"ต้นทุนแรงงาน/ยอดขายเพิ่ม, ","")&IF(E32>=3,"ร้องเรียนเยอะ, ",""))-2),IF(B32<0,"ยอดขายลด, ","")&IF(C32<0,"กำไรลด, ","")&IF(D32>0,"ต้นทุนแรงงาน/ยอดขายเพิ่ม, ","")&IF(E32>=3,"ร้องเรียนเยอะ, ","")))) | O32: =IF(A32="","",(B32<0)*1+(C32<0)*1+(D32>0)*1+(E32>=3)*1) | P32: =IF(A32="","",O32-IFERROR(B32/1000,0)) | Q32: =IF(A32="","",IFERROR(RANK(P32,$P$14:$P$36)+COUNTIF($P$14:P32,P32)-1,"")) | R32: =IF(A32="","",IFERROR(RANK(B32,$B$14:$B$36)+COUNTIF($B$14:B32,B32)-1,""))
F33: =IF(A33="","",IF((IF(B33<0,"ยอดขายลด, ","")&IF(C33<0,"กำไรลด, ","")&IF(D33>0,"ต้นทุนแรงงาน/ยอดขายเพิ่ม, ","")&IF(E33>=3,"ร้องเรียนเยอะ, ",""))="","ปกติ / ดี",IF(RIGHT(IF(B33<0,"ยอดขายลด, ","")&IF(C33<0,"กำไรลด, ","")&IF(D33>0,"ต้นทุนแรงงาน/ยอดขายเพิ่ม, ","")&IF(E33>=3,"ร้องเรียนเยอะ, ",""),2)=", ",LEFT(IF(B33<0,"ยอดขายลด, ","")&IF(C33<0,"กำไรลด, ","")&IF(D33>0,"ต้นทุนแรงงาน/ยอดขายเพิ่ม, ","")&IF(E33>=3,"ร้องเรียนเยอะ, ",""),LEN(IF(B33<0,"ยอดขายลด, ","")&IF(C33<0,"กำไรลด, ","")&IF(D33>0,"ต้นทุนแรงงาน/ยอดขายเพิ่ม, ","")&IF(E33>=3,"ร้องเรียนเยอะ, ",""))-2),IF(B33<0,"ยอดขายลด, ","")&IF(C33<0,"กำไรลด, ","")&IF(D33>0,"ต้นทุนแรงงาน/ยอดขายเพิ่ม, ","")&IF(E33>=3,"ร้องเรียนเยอะ, ","")))) | O33: =IF(A33="","",(B33<0)*1+(C33<0)*1+(D33>0)*1+(E33>=3)*1) | P33: =IF(A33="","",O33-IFERROR(B33/1000,0)) | Q33: =IF(A33="","",IFERROR(RANK(P33,$P$14:$P$36)+COUNTIF($P$14:P33,P33)-1,"")) | R33: =IF(A33="","",IFERROR(RANK(B33,$B$14:$B$36)+COUNTIF($B$14:B33,B33)-1,""))
F34: =IF(A34="","",IF((IF(B34<0,"ยอดขายลด, ","")&IF(C34<0,"กำไรลด, ","")&IF(D34>0,"ต้นทุนแรงงาน/ยอดขายเพิ่ม, ","")&IF(E34>=3,"ร้องเรียนเยอะ, ",""))="","ปกติ / ดี",IF(RIGHT(IF(B34<0,"ยอดขายลด, ","")&IF(C34<0,"กำไรลด, ","")&IF(D34>0,"ต้นทุนแรงงาน/ยอดขายเพิ่ม, ","")&IF(E34>=3,"ร้องเรียนเยอะ, ",""),2)=", ",LEFT(IF(B34<0,"ยอดขายลด, ","")&IF(C34<0,"กำไรลด, ","")&IF(D34>0,"ต้นทุนแรงงาน/ยอดขายเพิ่ม, ","")&IF(E34>=3,"ร้องเรียนเยอะ, ",""),LEN(IF(B34<0,"ยอดขายลด, ","")&IF(C34<0,"กำไรลด, ","")&IF(D34>0,"ต้นทุนแรงงาน/ยอดขายเพิ่ม, ","")&IF(E34>=3,"ร้องเรียนเยอะ, ",""))-2),IF(B34<0,"ยอดขายลด, ","")&IF(C34<0,"กำไรลด, ","")&IF(D34>0,"ต้นทุนแรงงาน/ยอดขายเพิ่ม, ","")&IF(E34>=3,"ร้องเรียนเยอะ, ","")))) | O34: =IF(A34="","",(B34<0)*1+(C34<0)*1+(D34>0)*1+(E34>=3)*1) | P34: =IF(A34="","",O34-IFERROR(B34/1000,0)) | Q34: =IF(A34="","",IFERROR(RANK(P34,$P$14:$P$36)+COUNTIF($P$14:P34,P34)-1,"")) | R34: =IF(A34="","",IFERROR(RANK(B34,$B$14:$B$36)+COUNTIF($B$14:B34,B34)-1,""))
F35: =IF(A35="","",IF((IF(B35<0,"ยอดขายลด, ","")&IF(C35<0,"กำไรลด, ","")&IF(D35>0,"ต้นทุนแรงงาน/ยอดขายเพิ่ม, ","")&IF(E35>=3,"ร้องเรียนเยอะ, ",""))="","ปกติ / ดี",IF(RIGHT(IF(B35<0,"ยอดขายลด, ","")&IF(C35<0,"กำไรลด, ","")&IF(D35>0,"ต้นทุนแรงงาน/ยอดขายเพิ่ม, ","")&IF(E35>=3,"ร้องเรียนเยอะ, ",""),2)=", ",LEFT(IF(B35<0,"ยอดขายลด, ","")&IF(C35<0,"กำไรลด, ","")&IF(D35>0,"ต้นทุนแรงงาน/ยอดขายเพิ่ม, ","")&IF(E35>=3,"ร้องเรียนเยอะ, ",""),LEN(IF(B35<0,"ยอดขายลด, ","")&IF(C35<0,"กำไรลด, ","")&IF(D35>0,"ต้นทุนแรงงาน/ยอดขายเพิ่ม, ","")&IF(E35>=3,"ร้องเรียนเยอะ, ",""))-2),IF(B35<0,"ยอดขายลด, ","")&IF(C35<0,"กำไรลด, ","")&IF(D35>0,"ต้นทุนแรงงาน/ยอดขายเพิ่ม, ","")&IF(E35>=3,"ร้องเรียนเยอะ, ","")))) | O35: =IF(A35="","",(B35<0)*1+(C35<0)*1+(D35>0)*1+(E35>=3)*1) | P35: =IF(A35="","",O35-IFERROR(B35/1000,0)) | Q35: =IF(A35="","",IFERROR(RANK(P35,$P$14:$P$36)+COUNTIF($P$14:P35,P35)-1,"")) | R35: =IF(A35="","",IFERROR(RANK(B35,$B$14:$B$36)+COUNTIF($B$14:B35,B35)-1,""))
F36: =IF(A36="","",IF((IF(B36<0,"ยอดขายลด, ","")&IF(C36<0,"กำไรลด, ","")&IF(D36>0,"ต้นทุนแรงงาน/ยอดขายเพิ่ม, ","")&IF(E36>=3,"ร้องเรียนเยอะ, ",""))="","ปกติ / ดี",IF(RIGHT(IF(B36<0,"ยอดขายลด, ","")&IF(C36<0,"กำไรลด, ","")&IF(D36>0,"ต้นทุนแรงงาน/ยอดขายเพิ่ม, ","")&IF(E36>=3,"ร้องเรียนเยอะ, ",""),2)=", ",LEFT(IF(B36<0,"ยอดขายลด, ","")&IF(C36<0,"กำไรลด, ","")&IF(D36>0,"ต้นทุนแรงงาน/ยอดขายเพิ่ม, ","")&IF(E36>=3,"ร้องเรียนเยอะ, ",""),LEN(IF(B36<0,"ยอดขายลด, ","")&IF(C36<0,"กำไรลด, ","")&IF(D36>0,"ต้นทุนแรงงาน/ยอดขายเพิ่ม, ","")&IF(E36>=3,"ร้องเรียนเยอะ, ",""))-2),IF(B36<0,"ยอดขายลด, ","")&IF(C36<0,"กำไรลด, ","")&IF(D36>0,"ต้นทุนแรงงาน/ยอดขายเพิ่ม, ","")&IF(E36>=3,"ร้องเรียนเยอะ, ","")))) | O36: =IF(A36="","",(B36<0)*1+(C36<0)*1+(D36>0)*1+(E36>=3)*1) | P36: =IF(A36="","",O36-IFERROR(B36/1000,0)) | Q36: =IF(A36="","",IFERROR(RANK(P36,$P$14:$P$36)+COUNTIF($P$14:P36,P36)-1,"")) | R36: =IF(A36="","",IFERROR(RANK(B36,$B$14:$B$36)+COUNTIF($B$14:B36,B36)-1,""))
A38: (Top 5 Best — by Sales Growth) | H38: (Needs Attention)
A39: # | B39: สาขา | E39: ยอดขาย YoY% | H39: # | I39: สาขา | K39: ประเด็นที่พบ
A40: 1 | B40: =IFERROR(INDEX($A$14:$A$36,MATCH(1,$R$14:$R$36,0)),"-") -> - | E40: =IFERROR(INDEX($B$14:$B$36,MATCH(1,$R$14:$R$36,0)),"") | H40: 1 | I40: =IFERROR(INDEX($A$14:$A$36,MATCH(1,$Q$14:$Q$36,0)),"-") -> - | K40: =IFERROR(INDEX($F$14:$F$36,MATCH(1,$Q$14:$Q$36,0)),"")
A41: 2 | B41: =IFERROR(INDEX($A$14:$A$36,MATCH(2,$R$14:$R$36,0)),"-") -> - | E41: =IFERROR(INDEX($B$14:$B$36,MATCH(2,$R$14:$R$36,0)),"") | H41: 2 | I41: =IFERROR(INDEX($A$14:$A$36,MATCH(2,$Q$14:$Q$36,0)),"-") -> - | K41: =IFERROR(INDEX($F$14:$F$36,MATCH(2,$Q$14:$Q$36,0)),"")
A42: 3 | B42: =IFERROR(INDEX($A$14:$A$36,MATCH(3,$R$14:$R$36,0)),"-") -> - | E42: =IFERROR(INDEX($B$14:$B$36,MATCH(3,$R$14:$R$36,0)),"") | H42: 3 | I42: =IFERROR(INDEX($A$14:$A$36,MATCH(3,$Q$14:$Q$36,0)),"-") -> - | K42: =IFERROR(INDEX($F$14:$F$36,MATCH(3,$Q$14:$Q$36,0)),"")
A43: 4 | B43: =IFERROR(INDEX($A$14:$A$36,MATCH(4,$R$14:$R$36,0)),"-") -> - | E43: =IFERROR(INDEX($B$14:$B$36,MATCH(4,$R$14:$R$36,0)),"") | H43: 4 | I43: =IFERROR(INDEX($A$14:$A$36,MATCH(4,$Q$14:$Q$36,0)),"-") -> - | K43: =IFERROR(INDEX($F$14:$F$36,MATCH(4,$Q$14:$Q$36,0)),"")
A44: 5 | B44: =IFERROR(INDEX($A$14:$A$36,MATCH(5,$R$14:$R$36,0)),"-") -> - | E44: =IFERROR(INDEX($B$14:$B$36,MATCH(5,$R$14:$R$36,0)),"") | H44: 5 | I44: =IFERROR(INDEX($A$14:$A$36,MATCH(5,$Q$14:$Q$36,0)),"-") -> - | K44: =IFERROR(INDEX($F$14:$F$36,MATCH(5,$Q$14:$Q$36,0)),"")
A65: เปรียบเทียบ Month-on-Month (MoM) — เดือนนี้ vs เดือนก่อนหน้า
A66: ="เดือนก่อนหน้า (Previous Month): "&IF(Aug!B130="","(ยังไม่ระบุ)",Aug!B130)&" | เดือนนี้ (Current Month): "&IF(Aug!B107="","(ยังไม่ระบุ)",Aug!B107) -> เดือนก่อนหน้า (Previous Month): (ยังไม่ระบุ) | เดือนนี้ (Current Month): (ยังไม่ระบุ)
A68: ยอดขายรวม (Sales) — MoM | D68: กำไร EBIT รวม (฿) — MoM | G68: ต้นทุนขาย COGs รวม — MoM | J68: ค่าแรง COL รวม (฿) — MoM
...
